<?xml version="1.0"?>
<robot xmlns:xacro="http://www.ros.org/wiki/xacro">

  <!-- Rosmaster X3 dimensions -->
  <xacro:property name="total_width" value="0.19940"/>
  <xacro:property name="wheel_width" value="0.0304"/>
  <xacro:property name="wheel_radius" value="0.0325"/>
  <xacro:property name="total_height" value="0.26225"/>
  <xacro:property name="base_length" value="0.300"/>
  <xacro:property name="centered_length" value="0.238"/>
  <xacro:property name="base_x_offset" value="${(centered_length - base_length) / 2}"/>
  <xacro:property name="base_size_x" value="${base_length}"/>
  <xacro:property name="base_size_y" value="${total_width - (2 * wheel_width)}"/>
  <xacro:property name="base_size_z" value="${total_height - (2 * wheel_radius)}"/>
  <xacro:property name="base_mass" value="4.6"/>

  <xacro:property name="wheel_mass" value="0.091"/>
  <xacro:property name="wheel_xoff" value="0.08"/>
  <xacro:property name="wheel_yoff" value="-0.01"/>
  <xacro:property name="wheel_separation" value="0.169"/>

  <xacro:macro name="rosmaster_wheel" params="side joint_name x_reflect y_reflect mesh_name">
    <link name="${side}_wheel_link">
      <visual>
        <origin xyz="0 0 0" rpy="${pi/2} 0 0"/>
        <geometry>
          <mesh filename="file://$(find anhc_robot_description)/meshes/rosmaster_x3/visual/${mesh_name}"/>
        </geometry>
      </visual>
      <collision>
        <origin xyz="0 0 0" rpy="${pi/2} 0 0"/>
        <geometry>
          <cylinder radius="${wheel_radius}" length="${wheel_width}"/>
        </geometry>
      </collision>
      <inertial>
        <origin xyz="0 0 0" rpy="0 0 0"/>
        <mass value="${wheel_mass}"/>
        <inertia
          ixx="${(wheel_mass/12.0) * (3*wheel_radius*wheel_radius + wheel_width*wheel_width)}" ixy="0" ixz="0"
          iyy="${(wheel_mass/2.0) * (wheel_radius*wheel_radius)}" iyz="0"
          izz="${(wheel_mass/12.0) * (3*wheel_radius*wheel_radius + wheel_width*wheel_width)}"/>
      </inertial>
    </link>

    <joint name="${joint_name}" type="continuous">
      <axis xyz="0 1 0"/>
      <parent link="base_link"/>
      <child link="${side}_wheel_link"/>
      <origin xyz="${x_reflect*wheel_xoff} ${y_reflect*(wheel_separation/2+wheel_yoff)} ${-wheel_radius}" rpy="0 0 0"/>
    </joint>

    <gazebo reference="${side}_wheel_link">
      <mu1>1.0</mu1>
      <mu2>0.0</mu2>
    </gazebo>
  </xacro:macro>

  <link name="base_footprint"/>
  <link name="base_link">
    <visual>
      <geometry>
        <mesh filename="file://$(find anhc_robot_description)/meshes/rosmaster_x3/visual/base_link_X3.STL"/>
      </geometry>
      <origin xyz="0 0 0" rpy="0 0 0"/>
    </visual>
    <collision>
      <geometry>
        <box size="${base_size_x} ${base_size_y} ${base_size_z}"/>
      </geometry>
      <origin xyz="${base_x_offset} 0 ${base_size_z/2 + wheel_radius/4}" rpy="0 0 0"/>
    </collision>
    <inertial>
      <origin xyz="${base_x_offset} 0 ${base_size_z/2 + wheel_radius/4}" rpy="0 0 0"/>
      <mass value="${base_mass}"/>
      <inertia
        ixx="${(1/12) * base_mass * ((base_size_y * base_size_y) + (base_size_z * base_size_z))}" ixy="0.0" ixz="0.0"
        iyy="${(1/12) * base_mass * ((base_size_x * base_size_x) + (base_size_z * base_size_z))}" iyz="0.0"
        izz="${(1/12) * base_mass * ((base_size_x * base_size_x) + (base_size_y * base_size_y))}"/>
    </inertial>
  </link>

  <joint name="base_joint" type="fixed">
    <parent link="base_footprint"/>
    <child link="base_link"/>
    <origin xyz="0 0 ${wheel_radius}" rpy="0 0 0"/>
  </joint>

  <xacro:rosmaster_wheel side="front_left"  joint_name="front_left_wheel_joint"  x_reflect=" 1" y_reflect=" 1" mesh_name="front_left_wheel_X3.STL"/>
  <xacro:rosmaster_wheel side="front_right" joint_name="front_right_wheel_joint" x_reflect=" 1" y_reflect="-1" mesh_name="front_right_wheel_X3.STL"/>
  <xacro:rosmaster_wheel side="back_left"   joint_name="back_left_wheel_joint"   x_reflect="-1" y_reflect=" 1" mesh_name="back_left_wheel_X3.STL"/>
  <xacro:rosmaster_wheel side="back_right"  joint_name="back_right_wheel_joint"  x_reflect="-1" y_reflect="-1" mesh_name="back_right_wheel_X3.STL"/>

</robot>
